<?xml version='1.0'?>

<sdf version='1.6'>
    <model name='simple_car'>
        <link name='ground'>
            <pose frame=''>0 0 -5 0 0 0</pose>
            <inertial>
                <pose frame=''>0 0 0 0 0 0</pose>
                <mass>0</mass>
                <inertia>
                    <ixx>0</ixx>
                    <ixy>0</ixy>
                    <ixz>0</ixz>
                    <iyy>0</iyy>
                    <iyz>0</iyz>
                    <izz>0</izz>
                </inertia>
            </inertial>
            <collision name='ground_collision'>
                <pose frame=''>0 0 0 0 0 0</pose>
                <geometry>
                    <box>
                        <size>100.0 100.0 10.0</size>
                    </box>
                </geometry>
            </collision>
            <visual name='ground_visual'>
                <pose frame=''>0 0 0 0 0 0</pose>
                <geometry>
                    <box>
                        <size>100.0 100.0 10.0</size>
                    </box>
                </geometry>
                <material>
                    <diffuse>0.54 0.54 0.54 0.9</diffuse>
                </material>
            </visual>
        </link>
        <link name='body'>
            <pose frame=''>0 0 1 0 0 0</pose>
            <inertial>
                <pose frame=''>0 0 0 0 0 0</pose>
                <mass>10.0</mass>
                <inertia>
                    <ixx>1.0</ixx>
                    <ixy>0</ixy>
                    <ixz>0</ixz>
                    <iyy>1.0</iyy>
                    <iyz>0</iyz>
                    <izz>1.0</izz>
                </inertia>
            </inertial>
            <collision name='body_collision'>
                <pose frame=''>0 0 0 0 0 0</pose>
                <geometry>
                    <box>
                        <size>1.5 1 1</size>
                    </box>
                </geometry>
            </collision>
            <visual name='body_visual'>
                <pose frame=''>0 0 0 0 0 0</pose>
                <geometry>
                    <box>
                        <size>1.5 1 1</size>
                    </box>
                </geometry>
                <material>
                    <diffuse>0.64 0.12 0.15 0.9</diffuse>
                </material>
            </visual>
        </link>
        <link name='body_x'/>
        <link name='body_y'/>
        <joint name='body_x_sensor' type='prismatic'>
            <child>body_x</child>
            <parent>ground</parent>
            <axis>
                <xyz>1 0 0</xyz>
                <dynamics>
                    <damping>0</damping>
                    <friction>0</friction>
                    <spring_reference>0</spring_reference>
                    <spring_stiffness>0</spring_stiffness>
                </dynamics>
                <use_parent_model_frame>1</use_parent_model_frame>
            </axis>
        </joint>
        <joint name='body_y_sensor' type='prismatic'>
            <child>body_y</child>
            <parent>body_x</parent>
            <axis>
                <xyz>0 1 0</xyz>
                <dynamics>
                    <damping>0</damping>
                    <friction>0</friction>
                    <spring_reference>0</spring_reference>
                    <spring_stiffness>0</spring_stiffness>
                </dynamics>
                <use_parent_model_frame>1</use_parent_model_frame>
            </axis>
        </joint>
        <joint name='body_theta' type='revolute'>
            <child>body</child>
            <parent>body_y</parent>
            <axis>
                <xyz>0 0 1</xyz>
                <dynamics>
                    <damping>0</damping>
                    <friction>1</friction>
                    <spring_reference>0</spring_reference>
                    <spring_stiffness>0</spring_stiffness>
                </dynamics>
                <use_parent_model_frame>1</use_parent_model_frame>
            </axis>
        </joint>

        <!-- Placeholder to make port dimensions match... -->
        <link name='dummy1'/>
        <joint name='velocity' type='prismatic'>
            <child>dummy1</child>
            <parent>ground</parent>
            <axis>
                <xyz>1 0 0</xyz>
                <use_parent_model_frame>1</use_parent_model_frame>
            </axis>
        </joint>

    </model>
</sdf>
